Workbook
Name Alappuzha: Others!$P$3:$P$18
Name Ernakulam: Others!$M$3:$M$18
Name Ex_MLA_Pic: INDEX('Ex MLA'!$C$3:$I$142,MATCH(Dashboard!$C$4,'Ex MLA'!$C$3:$C$142,0),7)
Name Idukki: Others!$N$3:$N$18
Name Kannur: Others!$G$3:$G$18
Name Kasaragod: Others!$F$3:$F$18
Name Kollam: Others!$R$3:$R$18
Name Kottayam: Others!$O$3:$O$18
Name Kozhikode: Others!$I$3:$I$18
Name LDF_Candidate_Symbol: INDEX(Symbols!$C$3:$E$98,MATCH(#REF!,Symbols!$C$3:$C$98,0),3)
Name LDF_Canidate_Pic: INDEX('Candidates'!$X$3:$AG$886,MATCH(#REF!,'Candidates'!$X$3:$X$886,0),10)
Name Malappuram: Others!$J$3:$J$18
Name NDA_Candidate_Pic: INDEX('Candidates'!$X$3:$AG$886,MATCH(#REF!,'Candidates'!$X$3:$X$886,0),10)
Name NDA_Candidate_Symbol: INDEX(Symbols!$C$3:$E$98,MATCH(#REF!,Symbols!$C$3:$C$98,0),3)
Name New_MLA_Pic: INDEX('Candidates'!$X$3:$AG$885,MATCH(Dashboard!$E$29,'Candidates'!$X$3:$X$885,0),10)
Name New_MLA_Ref: #REF!
Name New_RunnerUp_Ref: #REF!
Name No_Selected_Constituency: INDEX(Constituencies!$B$3:$D$142,MATCH(Dashboard!$C$4,Constituencies!$C$3:$C$142,0),1)
Name Palakkad: Others!$K$3:$K$18
Name Pathanamthitta: Others!$Q$3:$Q$18
Name Selected_Constituency_Ml: INDEX(Constituencies!$C$3:$D$142,MATCH(Dashboard!$C$4,Constituencies!$C$3:$C$142,0),2)
Name Symbol_Search: INDEX(Symbols!$C$3:$E$98,MATCH(#REF!,Symbols!$C$3:$C$98,0),3)
Name Thiruvananthapuram: Others!$S$3:$S$18
Name Thrissur: Others!$L$3:$L$18
Name UDF_Candiate_Pic: INDEX('Candidates'!$X$3:$AG$886,MATCH(#REF!,'Candidates'!$X$3:$X$886,0),10)
Name UDF_Candidate_Symbol: INDEX(Symbols!$C$3:$E$98,MATCH(#REF!,Symbols!$C$3:$C$98,0),3)
Name Wayanad: Others!$H$3:$H$18

Sheet About
B2: Kerala Assembly Election 2026: Master Analytics Suite
B4: Developed By
B5: Shamil Vakkaloor
B6: Founder, excelguru.co.in | Excel Expert & Data Enthusiast
B8: Project Overview
B9: This comprehensive electoral database provides a 360-degree view of all 140 Legislative Assembly Constituencies in Kerala. It is designed to track historical performance, voter demographics, and current candidate profiles for the 2026 Kerala Legislative Assembly (KLA) elections. While the dashboard allows for granular filtering—such as viewing the Indian Union Muslim League (IUML) strongholds in the Malappuram district—it is a statewide tool built for comparative political analysis.
B11: Data Source & Attribution
B12: The data driving this dashboard is sourced from the Open Data Kerala (ODK) initiative, specifically the KLA 2026 Project.
B13: Source: Open Data Kerala Election Portal
B14: Details: This project is a community-driven initiative that curates and democratizes election data, including candidate registries, alliance manifestos, and historical voter statistics. We acknowledge their effort in promoting transparency and supporting informed public participation through open data principles.
B16: Credits & Inspiration
B17: The design, logic, and interactive features of this dashboard were inspired by the work of Xl n Cad (Mr. Ajay Anand).
... B34: This dashboard is an independent analytical tool. While every effort has been made to ensure data accuracy using official and open-source records, users should refer to the Chief Electoral Officer (CEO) Kerala for final, official election results and notifications.

Sheet Dashboard
B3: District | C3: Kannur | F3: {=_xlfn.XLOOKUP(No_Selected_Constituency,New_MLA[Number],New_MLA[Member])} -> M. Vijin | I3: {=_xlfn.XLOOKUP(No_Selected_Constituency,Ex_MLA[Number],Ex_MLA[Member])} -> M Vijin
B4: Constituency | C4: Kalliasseri | F4: {="Age: "&_xlfn.XLOOKUP(No_Selected_Constituency,New_MLA[Number],New_MLA[Age])} -> Age: 36 | I4: {="Age: "&_xlfn.XLOOKUP(No_Selected_Constituency,Ex_MLA[Number],Ex_MLA[Age])} -> Age: 31
F5: {="Party: "&_xlfn.XLOOKUP(No_Selected_Constituency,New_MLA[Number],New_MLA[Party])} -> Party: CPI(M) | I5: {="Party: "&_xlfn.XLOOKUP(No_Selected_Constituency,Ex_MLA[Number],Ex_MLA[Party])} -> Party: CPM
F6: {=_xlfn.XLOOKUP(No_Selected_Constituency,New_MLA[Number],New_MLA[Alliance])} -> LDF | I6: {=_xlfn.XLOOKUP(No_Selected_Constituency,Ex_MLA[Number],Ex_MLA[Alliance])} -> LDF
B7: Parliament | C7: {=_xlfn.XLOOKUP(No_Selected_Constituency,Constituency[Number],Constituency[Loksabha])} -> Kasaragod | F7: {="Votes Received: "&_xlfn.XLOOKUP(No_Selected_Constituency,New_MLA[Number],New_MLA[Member_Votes])} -> Votes Received: 81428 | I7: {="Votes: "&_xlfn.XLOOKUP(No_Selected_Constituency,Ex_MLA[Number],Ex_MLA[Member_Votes])} -> Votes: 88252
B8: Male Voters | C8: {=_xlfn.XLOOKUP(No_Selected_Constituency,Constituency[Number],Constituency[Male_Voters])} -> 97648 | F8: {="Percentage: "&ROUND((_xlfn.XLOOKUP(No_Selected_Constituency,New_MLA[Number],New_MLA[Member_Perc])*100),2)&"%"} -> Percentage: 50.93% | I8: {="Perc: "&ROUND((_xlfn.XLOOKUP(No_Selected_Constituency,Ex_MLA[Number],Ex_MLA[Member_Perc])*100),2)&"%"} -> Perc: 60.62%
B9: Female Voters | C9: {=_xlfn.XLOOKUP(No_Selected_Constituency,Constituency[Number],Constituency[Femal_Voters])} -> 106147 | F9: {="Margin: "&_xlfn.XLOOKUP(No_Selected_Constituency,New_MLA[Number],New_MLA[Margin])} -> Margin: 18433 | I9: {="Margin: "&_xlfn.XLOOKUP(No_Selected_Constituency,Ex_MLA[Number],Ex_MLA[Margin])} -> Margin: 44393
B10: Total Voters | C10: {=_xlfn.XLOOKUP(No_Selected_Constituency,Constituency[Number],Constituency[Total_Voters])} -> 203796
B11: Votes Polled | C11: {=SUMIFS(Result2026[Votes],Result2026[Number],No_Selected_Constituency)} -> 159867 | E11: First Runner Up
B12: Percentage | C12: {=_xlfn.XLOOKUP(No_Selected_Constituency,Result2026[Number],Result2026[Percentage])} -> 76.99
B13: Resarvation | C13: {=_xlfn.XLOOKUP(No_Selected_Constituency,Constituency[Number],Constituency[Reservation])} -> GEN
B15: 2026 | C15: {=_xlfn.XLOOKUP(No_Selected_Constituency,New_MLA[Number],New_MLA[Member]&" - "&_xlfn.XLOOKUP(No_Selected_Constituency,New_MLA[Number],New_MLA[Alliance]))} -> M. Vijin - LDF
B16: 2021 | C16: {=_xlfn._xlws.FILTER(Vote_History[Winner_Name],(Vote_History[Year]=B16)*(Vote_History[constituency]=$C$4))&" - "&_xlfn._xlws.FILTER(Vote_History[Winner__Alliance],(Vote_History[Year]=B16)*(Vote_History[constituency]=$C$4))} -> M Vijin - LDF
B17: 2016 | C17: {=_xlfn._xlws.FILTER(Vote_History[Winner_Name],(Vote_History[Year]=B17)*(Vote_History[constituency]=$C$4))&" - "&_xlfn._xlws.FILTER(Vote_History[Winner__Alliance],(Vote_History[Year]=B17)*(Vote_History[constituency]=$C$4))} -> T V Rajesh - LDF
B18: 2011 | C18: {=_xlfn._xlws.FILTER(Vote_History[Winner_Name],(Vote_History[Year]=B18)*(Vote_History[constituency]=$C$4))&" - "&_xlfn._xlws.FILTER(Vote_History[Winner__Alliance],(Vote_History[Year]=B18)*(Vote_History[constituency]=$C$4))} -> T.V. Rajesh - LDF
B28: Const ML | C28: =INDEX(Constituencies!$C$3:$D$142,MATCH(Dashboard!$C$4,Constituencies!$C$3:$C$142,0),2) -> കല്ല്യാശ്ശേരി | E28: New MLA Ref
B29: Const No | C29: =INDEX(Constituencies!$B$3:$D$142,MATCH(Dashboard!$C$4,Constituencies!$C$3:$C$142,0),1) -> 7 | E29: =INDEX('New MLA'!$C$3:$F$142,MATCH(Dashboard!$C$4,'New MLA'!$C$3:$C$142,0),4) -> 26kla007
E31: Runner Up
E32: {=_xlfn._xlws.FILTER(Result2026[Candidate_Ref],(Result2026[Position]=2)*(Result2026[Number]=No_Selected_Constituency))} -> 26kla147
E34: 2nd Runner Up
E35: {=_xlfn._xlws.FILTER(Result2026[Candidate_Ref],(Result2026[Position]=3)*(Result2026[Number]=No_Selected_Constituency))} -> 26kla287
E37: Ex Mla
E38: =INDEX('Ex MLA'!$C$3:$I$142,MATCH(Dashboard!$C$4,'Ex MLA'!$C$3:$C$142,0),7) -> 0

Sheet Candidates
B2: number | C2: name | D2: nameMalayalam | E2: district | F2: districtMalayalam | G2: districtQid | H2: qid | I2: reservation | J2: pollingBooths | K2: votersMale | L2: votersFemale | M2: votersTransgender | N2: votersTotal | O2: candidates__alliance | P2: candidates__party | Q2: candidates__name | R2: candidates__malayalam | S2: candidates__wikidata | T2: candidates__gender | U2: candidates__age | V2: candidates__candidateId | W2: candidates__photo | X2: candidates__reference | Y2: candidates__symbol | Z2: candidates__archiveUrl | AA2: candidates__aparanTag | AB2: candidates__sittingMLA | AC2: candidates__mlaTrack | AD2: candidates__eduTag | AE2: candidates__ballotOrder | AF2: fightIndex | AG2: pic
B3: 1 | C3: Manjeshwaram | D3: മഞ്ചേശ്വരം | E3: Kasaragod | F3: കാസർഗോഡ് ജില്ല | G3: Q1419703 | H3: Q13113782 | J3: 229 | K3: 115801 | L3: 114312 | M3: 0 | N3: 230113 | O3: UDF | P3: IUML | Q3: A. K. M. Ashraf | R3: എ. കെ. എം. അഷ്റഫ് | S3: Q106687787 | T3: male | U3: 48 | V3: 2644 | W3: AKMAS-2026-20260325102628.jpg | X3: 26kla141 | Y3: Ladder | Z3: mlat.26kla141_kochi.akmashraf | AB3: YES | AC3: https://mlatrack.com/15kla/profiles/mlas/a_k_m_ashraf_m | AD3: Higher Secondary | AE3: 1 | AF3: 68.8
B4: 1 | O4: LDF | P4: CPI(M) | Q4: K. R. Jayananda | R4: കെ. ആർ. ജയാനന്ദ | T4: male | U4: 58 | V4: 684 | W4: JAYAN-2026-20260324054718.jpg | X4: 26kla001 | Y4: Hammer, Sickle and Star | Z4: mlat.26kla001_thrithala.krjayananda | AD4: High School | AE4: 2
B5: 1 | O5: Others | P5: BSP | Q5: Sanjeeva | R5: സഞ്ജീവ | T5: male | U5: 55 | V5: 2162 | W5: SANJE-2026-20260324055326.jpg | X5: 26kla972 | Y5: Elephant | Z5: mlat.26kla972_muvattupuzha.sanjeeva | AE5: 3
B6: 1 | O6: NDA | P6: BJP | Q6: K. Surendran | R6: കെ. സുരേന്ദ്രൻ | S6: Q25587200 | T6: male | U6: 56 | V6: 2840 | W6: KSURE-2026-20260324053843.jpg | X6: 26kla281 | Y6: Lotus | Z6: mlat.26kla281_manjeshwaram.ksurendran | AD6: Degree | AE6: 4
B7: 1 | O7: Others | Q7: Kannur Abdulla Master | R7: കണ്ണൂർ അബ്ദുള്ള മാസ്റ്റർ | T7: male | U7: 66 | V7: 738 | W7: ABDUL-2026-20260324053104.jpg | X7: 26kla812 | Y7: Gas Cylinder | Z7: mlat.26kla812_kannur.kannurabdullamaster | AE7: 5
B8: 1 | O8: Others | Q8: Abdul Latheef I | R8: അബ്ദുൾ ലത്തീഫ് ഐ | T8: male | U8: 38 | V8: 3319 | W8: ABDUL-2026-20260323072045.jpg | X8: 26kla696 | Y8: Television | Z8: mlat.26kla696_udma.abdullatheefi | AE8: 6
B9: 1 | O9: Others | Q9: Gean Lavina Monteiro | R9: ഗീൻ ലാവിന മൊണ്ടീറോ | T9: female | U9: 56 | V9: 3816 | W9: GEANL-2026-20260324052456.jpg | X9: 26kla784 | Y9: Battery Torch | Z9: mlat.26kla784_angamaly.geanlavinamonteiro | AE9: 7
B10: 1 | O10: Others | Q10: John D' Souza | R10: ജോൺ ഡിസൂസ | T10: male | U10: 63 | V10: 2064 | W10: JOHND-2026-20260324054042.jpg | X10: 26kla802 | Y10: Truck | Z10: mlat.26kla802_devikulam.johndsouza | AE10: 8
B11: 1 | O11: Others | Q11: Mohammed Ashraf | R11: മുഹമ്മദ് അഷ്‌റഫ് | T11: male | U11: 43 | V11: 3873 | W11: MOHAM-2026-20260324052952.jpg | X11: 26kla853 | Y11: Bat | Z11: mlat.26kla853_chadayamangalam.mohammedashraf | AA11: 26kla141 | AE11: 9
B12: 1 | O12: Others | Q12: Mohammed Ashraf K A | R12: മുഹമ്മദ് അഷ്‌റഫ് കെ എ | T12: male | U12: 51 | V12: 3723 | W12: MOHAM-2026-20260324054222.jpg | X12: 26kla854 | Y12: Gas Stove | Z12: mlat.26kla854_chirayinkeezhu.mohammedashrafka | AA12: 26kla141 | AE12: 10
B13: 1 | O13: Others | Q13: D Surendran Nair | R13: ഡി സുരേന്ദ്രൻ നായർ | T13: male | U13: 63 | V13: 1915 | W13: DSURE-2026-20260325103644.jpg | X13: 26kla774 | Y13: Diamond | Z13: mlat.26kla774_kottakkal.dsurendrannair | AA13: 26kla281 | AE13: 11
B14: 2 | C14: Kasaragod | D14: കാസർഗോഡ് | E14: Kasaragod | F14: കാസർഗോഡ് ജില്ല | G14: Q1419703 | H14: Q13111222 | J14: 218 | K14: 105524 | L14: 105399 | M14: 0 | N14: 210923 | O14: NDA | P14: BJP | Q14: Ashwini M.L. | R14: അശ്വിനി എം. എൽ. | T14: female | U14: 40 | V14: 1899 | W14: ASHWI-2026-20260323045231.jpg | X14: 26kla282 | Y14: Lotus | Z14: mlat.26kla282_ollur.ashwiniml | AD14: Diploma | AE14: 1 | AF14: 48.7
B15: 2 | O15: UDF | P15: IUML | Q15: Kallatra Mahin Haji | R15: കല്ലട്ര മാഹിൻ ഹാജി | T15: male | U15: 62 | V15: 1592 | W15: MAHIN-2026-20260323032302.jpg | X15: 26kla142 | Y15: Ladder | Z15: mlat.26kla142_thodupuzha.kallatramahin | AD15: Degree | AE15: 2
B16: 2 | O16: Others | Q16: Mohammed Ali Fathah B M | R16: മുഹമ്മദ് അലി ഫത്താഹ് ബി എം | T16: male | U16: 47 | V16: 1835 | W16: MOHAM-2026-20260323043319.jpg | X16: 26kla852 | Y16: Bat | Z16: mlat.26kla852_kottarakkara.mohammedalifathahbm | AE16: 3
B17: 2 | O17: Others | Q17: Shanavas A A | R17: ഷാനവാസ് എ എ | T17: male | U17: 44 | V17: 1767 | W17: SHANA-2026-20260323041955.jpg | X17: 26kla994 | Y17: Diamond | Z17: mlat.26kla994_kongad.shanavasaa | AA17: 26kla002 | AE17: 4
B18: 2 | O18: LDF | P18: Independent (INL Support) | Q18: Shanavas Padhoor | R18: ഷാനവാസ് പാദൂർ | T18: male | U18: 46 | V18: 1734 | W18: SHANA-2026-20260323041134.jpg | X18: 26kla002 | Y18: Battery Torch | Z18: mlat.26kla002_vallikkunnu.shanavaspadhoor | AD18: Higher Secondary | AE18: 5
B19: 3 | C19: Udma | D19: ഉദുമ | E19: Kasaragod | F19: കാസർഗോഡ് ജില്ല | G19: Q1419703 | H19: Q13110513 | J19: 237 | K19: 112166 | L19: 116342 | M19: 4 | N19: 228512 | O19: LDF | P19: CPI(M) | Q19: C. H. Kunhambu | R19: സി. എച്ച്. കുഞ്ഞമ്പു | S19: Q13115063 | T19: male | U19: 66 | V19: 809 | W19: CHKUN-2026-20260321054309.jpg | X19: 26kla003 | Y19: Hammer, Sickle and Star | Z19: mlat.26kla003_elathur.chkunhambu | AB19: YES | AC19: https://mlatrack.com/15kla/profiles/mlas/c_h_kunhambu_u | AD19: Professional Degree | AE19: 1 | AF19: 52.2
B20: 3 | O20: UDF | P20: INC | Q20: Neelakantan | R20: നീലകണ്ഠൻ | T20: male | U20: 62 | V20: 2588 | W20: NEELA-2026-20260324054847.jpg | X20: 26kla143 | Y20: Hand | Z20: mlat.26kla143_kozhikodesouth.neelakandan | AD20: Degree | AE20: 2
B21: 3 | O21: NDA | P21: BJP | Q21: Manulal Meloth | R21: മനുലാൽ മേലോത്ത് | T21: male | U21: 39 | V21: 1093 | W21: MANUL-2026-20260321065203.jpg | X21: 26kla283 | Y21: Lotus | Z21: mlat.26kla283_piravom.manulalm | AD21: Degree | AE21: 3
B22: 3 | O22: Others | Q22: Kunhampu P P S/o Raman | R22: കുഞ്ഞമ്പു പി പി S/O രാമൻ | T22: male | U22: 79 | V22: 2782 | W22: KUNHA-2026-20260323065721.jpg | X22: 26kla834 | Y22: Binoculars | Z22: mlat.26kla834_palakkad.kunhampupp | AA22: 26kla003 | AE22: 4
B23: 3 | O23: Others | Q23: Kunhiraman | R23: കുഞ്ഞിരാമൻ | T23: male | U23: 55 | V23: 1293 | W23: KUNHI-2026-20260323014341.jpg | X23: 26kla835 | Y23: Bat | Z23: mlat.26kla835_kuttanad.kunhiraman | AE23: 5
B24: 3 | O24: Others | Q24: Naseer | R24: നസീർ | T24: male | U24: 45 | V24: 2517 | W24: 1774162897pic.jpg | X24: 26kla879 | Y24: Drilling Machine | Z24: mlat.26kla879_thanur.naseer | AE24: 6
B25: 4 | C25: Kanhangad | D25: കാഞ്ഞങ്ങാട് | E25: Kasaragod | F25: കാസർഗോഡ് ജില്ല | G25: Q1419703 | H25: Q13111113 | J25: 239 | K25: 109008 | L25: 114966 | M25: 6 | N25: 223980 | O25: LDF | P25: CPI | Q25: Govindan Pallikkappil | R25: ഗോവിന്ദൻ പള്ളിക്കാപ്പിൽ | T25: male | U25: 60 | V25: 1906 | W25: GOVIN-2026-20260321035850.jpg | X25: 26kla004 | Y25: Ears of Corn and Sickle | Z25: mlat.26kla004_malappuram.govindanpallikappil | AD25: Professional Degree | AE25: 1 | AF25: 26.9
B26: 4 | O26: NDA | P26: BJP | Q26: M. Balraj | R26: എം. ബൽരാജ് | T26: male | U26: 58 | V26: 693 | W26: MBALA-2026-20260321044830.jpg | X26: 26kla284 | Y26: Lotus | Z26: mlat.26kla284_perumbavoor.mbalaraj | AD26: High School | AE26: 2
B27: 4 | O27: Others | P27: BSP | Q27: B. Vijayakumar | R27: ബി. വിജയകുമാർ | T27: male | U27: 54 | V27: 1610 | W27: VIJAY-2026-20260323034051.jpg | X27: 26kla1062 | Y27: Elephant | Z27: mlat.26kla1062_karunagapally.bvijayakumar | AE27: 3
B28: 4 | O28: UDF | P28: KEC | Q28: Shyji Ottapalli | R28: ഷൈജി ഒറ്റപ്പള്ളി | T28: male | U28: 53 | V28: 1743 | W28: SHAIJ-2026-20260323040034.jpg | X28: 26kla144 | Y28: Auto Rikshaw | Z28: mlat.26kla144_thodupuzha.shaiji | AD28: Diploma | AE28: 4
B29: 5 | C29: Thrikaripur | D29: തൃക്കരിപ്പൂർ | E29: Kasaragod | F29: കാസർഗോഡ് ജില്ല | G29: Q1419703 | H29: Q16137696 | J29: 218 | K29: 102044 | L29: 108044 | M29: 2 | N29: 210090 | O29: LDF | P29: CPI(M) | Q29: Dr. V. P. P. Mustafa | R29: ഡോ. വി. പി. പി. മുസ്തഫ | T29: male | U29: 54 | V29: 893 | W29: MUSTA-2026-20260321062452.jpg | X29: 26kla005 | Y29: Hammer, Sickle and Star | Z29: mlat.26kla005_thavanur.mustafavpp | AD29: Doctorate Degree | AE29: 1 | AF29: 34.2
B30: 5 | O30: UDF | P30: INC | Q30: Sandeep Varier | R30: സന്ദീപ് വാര്യർ | T30: male | U30: 44 | V30: 3328 | W30: SANDE-2026-20260323075148.jpg | X30: 26kla145 | Y30: Hand | Z30: mlat.26kla145_kochi.sandeepg | AD30: Diploma | AE30: 2
B31: 5 | O31: NDA | P31: TTP | Q31: Ravi Kulangara | R31: രവി കുളങ്ങര | T31: male | U31: 58 | V31: 857 | W31: RAVIK-2026-20260321045159.jpg | X31: 26kla285 | Y31: Jackfruit | Z31: mlat.26kla285_vattiyoorkavu.ravikulangara | AD31: Master Degree | AE31: 3
B32: 5 | O32: Others | Q32: Musthafa P P | R32: മുസ്തഫ പി പി | T32: male | U32: 41 | V32: 3762 | W32: MUSTH-2026-20260323090035.jpg | X32: 26kla871 | Y32: Scissors | Z32: mlat.26kla871_thalassery.musthafapp | AA32: 26kla005 | AE32: 4
B33: 5 | O33: Others | Q33: Musthafa V P | R33: മുസ്തഫ വി പി | T33: male | U33: 51 | V33: 3830 | W33: MUSTH-2026-20260323091005.jpg | X33: 26kla872 | Y33: Chain | Z33: mlat.26kla872_angamaly.musthafavp | AA33: 26kla005 | AE33: 5
B34: 5 | O34: Others | Q34: Sandeep Elatt | R34: സന്ദീപ് എലാട്ട് | T34: male | U34: 36 | V34: 3555 | W34: SANDE-2026-20260323083720.jpg | X34: 26kla969 | Y34: Gas Cylinder | Z34: mlat.26kla969_attingal.sandeepelatt | AA34: 26kla145 | AE34: 6
B35: 6 | C35: Payyanur | D35: പയ്യന്നൂർ | E35: Kannur | F35: കണ്ണൂർ ജില്ല | G35: Q2980652 | H35: Q17379122 | J35: 192 | K35: 91006 | L35: 97926 | M35: 3 | N35: 188935 | O35: NDA | P35: BJP | Q35: A. P. Gangadharan | R35: എ. പി. ഗംഗാധരൻ | T35: male | U35: 62 | V35: 1574 | W35: GANGA-2026-20260325111029.jpg | X35: 26kla286 | Y35: Lotus | Z35: mlat.26kla286_paravur.apgangadharan | AD35: High School | AE35: 1 | AF35: 8.9
B36: 6 | O36: LDF | P36: CPI(M) | Q36: T. I. Madhusoodanan | R36: ടി. ഐ. മധുസൂദനൻ | S36: Q106679753 | T36: male | U36: 65 | V36: 1712 | W36: TIMAD-2026-20260325110807.jpg | X36: 26kla006 | Y36: Hammer, Sickle and Star | Z36: mlat.26kla006_thavanur.timadusoodhanan | AB36: YES | AC36: https://mlatrack.com/15kla/profiles/mlas/t_i_madusoodhanan_p | AD36: Degree | AE36: 2
B37: 6 | O37: UDF | P37: Independent (RSP support) | Q37: V. Kunjikrishnan | R37: വി. കുഞ്ഞികൃഷ്ണൻ | T37: male | U37: 74 | V37: 1723 | W37: KUNHI-2026-20260325110914.jpg | X37: 26kla146 | Y37: Electric Pole | Z37: mlat.26kla146_chadayamangalam.vkunhikrishnan | AD37: Professional Degree | AE37: 3
B38: 6 | O38: Others | Q38: Sandeep V. K. | R38: സന്ദീപ് വി. കെ. | T38: male | U38: 38 | V38: 2440 | W38: SANDE-2026-20260325110724.jpg | X38: 26kla971 | Y38: Table | Z38: mlat.26kla971_peravoor.sandeepvk | AE38: 4
B39: 7 | C39: Kalliasseri | D39: കല്ല്യാശ്ശേരി | E39: Kannur | F39: കണ്ണൂർ ജില്ല | G39: Q2980652 | H39: Q13111077 | J39: 184 | K39: 97648 | L39: 106147 | M39: 1 | N39: 203796 | O39: UDF | P39: INC | Q39: Adv. Rajeevan Kappacheri | R39: അഡ്വ. രാജീവൻ കപ്പച്ചേരി | T39: male | U39: 57 | V39: 1857 | W39: ADVR-2026-20260326125406.jpg | X39: 26kla147 | Y39: Hand | Z39: mlat.26kla147_kothamangalam.rajeevankappacheri | AD39: Diploma | AE39: 1 | AF39: 3.3
B40: 7 | O40: LDF | P40: CPI(M) | Q40: M. Vijin | R40: എം. വിജിൻ | S40: Q106687789 | T40: male | U40: 36 | V40: 444 | W40: MVIJI-2026-20260326125308.jpg | X40: 26kla007 | Y40: Hammer, Sickle and Star | Z40: mlat.26kla007_azhikode.mvijin | AB40: YES | AC40: https://mlatrack.com/15kla/profiles/mlas/m_vijin_k | AD40: Master Degree | AE40: 2
B41: 7 | O41: NDA | P41: BJP | Q41: A.V. Sanil Kumar | R41: എ. വി. സനിൽ കുമാർ | T41: male | U41: 47 | V41: 1587 | W41: SANIL-2026-20260326125338.jpg | X41: 26kla287 | Y41: Lotus | Z41: mlat.26kla287_perambra.sanilav | AD41: High School | AE41: 3
...

Sheet Symbols
B2: S.N | C2: Symbol | D2: Party | E2: Image
B3: 1 | C3: Air Conditioner
B4: 2 | C4: Almirah
B5: 3 | C5: Auto Rikshaw | D5: KEC
B6: 4 | C6: Baby Walker | D6: BJP
B7: 5 | C7: Balloon
B8: 6 | C8: Bangles
B9: 7 | C9: Bat
B10: 8 | C10: Batsman
B11: 9 | C11: Battery Torch
B12: 10 | C12: Bead Necklace
B13: 11 | C13: Belt
B14: 12 | C14: Bench
B15: 13 | C15: Bicycle Pump
B16: 14 | C16: Binoculars
B17: 15 | C17: Black Board | D17: CPIML Red Star
B18: 16 | C18: Boat with man and Sail
B19: 17 | C19: Broom
B20: 18 | C20: Brush
B21: 19 | C21: Bucket
B22: 20 | C22: Calculator
B23: 21 | C23: Camera
B24: 22 | C24: Capsicum
B25: 23 | C25: Cauli Flower
B26: 24 | C26: CCTV Camera
B27: 25 | C27: Chain
B28: 26 | C28: Chappals
B29: 27 | C29: Clock | D29: NCP
B30: 28 | C30: Coat
B31: 29 | C31: Coconut Farm
B32: 30 | C32: Colour Tray and Brush
B33: 31 | C33: Computer
B34: 32 | C34: Cutting plier
B35: 33 | C35: Diamond
B36: 34 | C36: Dish Antenna
B37: 35 | C37: Drilling Machine
B38: 36 | C38: Dustbin
B39: 37 | C39: Ears of Corn and Sickle | D39: CPI
B40: 38 | C40: Electric Pole
B41: 39 | C41: Elephant | D41: BSP
...

Sheet Constituencies
B2: Number | C2: Constituency | D2: Constituency_Ml | E2: Loksabha | F2: District | G2: District_Ml | H2: District_qid | I2: qid | J2: Reservation | K2: Male_Voters | L2: Femal_Voters | M2: Total_Voters | N2: Polling Booths
B3: 1 | C3: {=_xlfn.XLOOKUP(Constituencies!$B3,Candidates[[number]:[number]],Candidates[name])} -> Manjeshwaram | D3: {=_xlfn.XLOOKUP(Constituencies!$B3,Candidates[[number]:[number]],Candidates[nameMalayalam])} -> മഞ്ചേശ്വരം | E3: =_xlfn.XLOOKUP(Constituency[[#This Row],[Constituency]],Vote_History[constituency],Vote_History[ParliamentaryConstituency]) -> Kasaragod | F3: {=_xlfn.XLOOKUP(Constituencies!$B3,Candidates[[number]:[number]],Candidates[district])} -> Kasaragod | G3: {=_xlfn.XLOOKUP(Constituencies!$B3,Candidates[[number]:[number]],Candidates[districtMalayalam])} -> കാസർഗോഡ് ജില്ല | H3: {=_xlfn.XLOOKUP(Constituencies!$B3,Candidates[[number]:[number]],Candidates[districtQid])} -> Q1419703 | I3: {=_xlfn.XLOOKUP(Constituencies!$B3,Candidates[[number]:[number]],Candidates[qid])} -> Q13113782 | J3: {=IF(_xlfn.XLOOKUP(Constituencies!$B3,Candidates[[number]:[number]],Candidates[reservation])="","GEN", _xlfn.XLOOKUP(Constituencies!$B3,Candidates[[number]:[number]],Candidates[reservation]))} -> GEN | K3: {=_xlfn.XLOOKUP(Constituencies!$B3,Candidates[[number]:[number]],Candidates[votersMale])} -> 115801 | L3: {=_xlfn.XLOOKUP(Constituencies!$B3,Candidates[[number]:[number]],Candidates[votersFemale])} -> 114312 | M3: {=_xlfn.XLOOKUP(Constituencies!$B3,Candidates[[number]:[number]],Candidates[votersTotal])} -> 230113 | N3: {=_xlfn.XLOOKUP(Constituencies!$B3,Candidates[[number]:[number]],Candidates[pollingBooths])} -> 229
B4: 2 | C4: {=_xlfn.XLOOKUP(Constituencies!$B4,Candidates[[number]:[number]],Candidates[name])} -> Kasaragod | D4: {=_xlfn.XLOOKUP(Constituencies!$B4,Candidates[[number]:[number]],Candidates[nameMalayalam])} -> കാസർഗോഡ് | E4: =_xlfn.XLOOKUP(Constituency[[#This Row],[Constituency]],Vote_History[constituency],Vote_History[ParliamentaryConstituency]) -> Kasaragod | F4: {=_xlfn.XLOOKUP(Constituencies!$B4,Candidates[[number]:[number]],Candidates[district])} -> Kasaragod | G4: {=_xlfn.XLOOKUP(Constituencies!$B4,Candidates[[number]:[number]],Candidates[districtMalayalam])} -> കാസർഗോഡ് ജില്ല | H4: {=_xlfn.XLOOKUP(Constituencies!$B4,Candidates[[number]:[number]],Candidates[districtQid])} -> Q1419703 | I4: {=_xlfn.XLOOKUP(Constituencies!$B4,Candidates[[number]:[number]],Candidates[qid])} -> Q13111222 | J4: {=IF(_xlfn.XLOOKUP(Constituencies!$B4,Candidates[[number]:[number]],Candidates[reservation])="","GEN", _xlfn.XLOOKUP(Constituencies!$B4,Candidates[[number]:[number]],Candidates[reservation]))} -> GEN | K4: {=_xlfn.XLOOKUP(Constituencies!$B4,Candidates[[number]:[number]],Candidates[votersMale])} -> 105524 | L4: {=_xlfn.XLOOKUP(Constituencies!$B4,Candidates[[number]:[number]],Candidates[votersFemale])} -> 105399 | M4: {=_xlfn.XLOOKUP(Constituencies!$B4,Candidates[[number]:[number]],Candidates[votersTotal])} -> 210923 | N4: {=_xlfn.XLOOKUP(Constituencies!$B4,Candidates[[number]:[number]],Candidates[pollingBooths])} -> 218
B5: 3 | C5: {=_xlfn.XLOOKUP(Constituencies!$B5,Candidates[[number]:[number]],Candidates[name])} -> Udma | D5: {=_xlfn.XLOOKUP(Constituencies!$B5,Candidates[[number]:[number]],Candidates[nameMalayalam])} -> ഉദുമ | E5: =_xlfn.XLOOKUP(Constituency[[#This Row],[Constituency]],Vote_History[constituency],Vote_History[ParliamentaryConstituency]) -> Kasaragod | F5: {=_xlfn.XLOOKUP(Constituencies!$B5,Candidates[[number]:[number]],Candidates[district])} -> Kasaragod | G5: {=_xlfn.XLOOKUP(Constituencies!$B5,Candidates[[number]:[number]],Candidates[districtMalayalam])} -> കാസർഗോഡ് ജില്ല | H5: {=_xlfn.XLOOKUP(Constituencies!$B5,Candidates[[number]:[number]],Candidates[districtQid])} -> Q1419703 | I5: {=_xlfn.XLOOKUP(Constituencies!$B5,Candidates[[number]:[number]],Candidates[qid])} -> Q13110513 | J5: {=IF(_xlfn.XLOOKUP(Constituencies!$B5,Candidates[[number]:[number]],Candidates[reservation])="","GEN", _xlfn.XLOOKUP(Constituencies!$B5,Candidates[[number]:[number]],Candidates[reservation]))} -> GEN | K5: {=_xlfn.XLOOKUP(Constituencies!$B5,Candidates[[number]:[number]],Candidates[votersMale])} -> 112166 | L5: {=_xlfn.XLOOKUP(Constituencies!$B5,Candidates[[number]:[number]],Candidates[votersFemale])} -> 116342 | M5: {=_xlfn.XLOOKUP(Constituencies!$B5,Candidates[[number]:[number]],Candidates[votersTotal])} -> 228512 | N5: {=_xlfn.XLOOKUP(Constituencies!$B5,Candidates[[number]:[number]],Candidates[pollingBooths])} -> 237
B6: 4 | C6: {=_xlfn.XLOOKUP(Constituencies!$B6,Candidates[[number]:[number]],Candidates[name])} -> Kanhangad | D6: {=_xlfn.XLOOKUP(Constituencies!$B6,Candidates[[number]:[number]],Candidates[nameMalayalam])} -> കാഞ്ഞങ്ങാട് | E6: =_xlfn.XLOOKUP(Constituency[[#This Row],[Constituency]],Vote_History[constituency],Vote_History[ParliamentaryConstituency]) -> Kasaragod | F6: {=_xlfn.XLOOKUP(Constituencies!$B6,Candidates[[number]:[number]],Candidates[district])} -> Kasaragod | G6: {=_xlfn.XLOOKUP(Constituencies!$B6,Candidates[[number]:[number]],Candidates[districtMalayalam])} -> കാസർഗോഡ് ജില്ല | H6: {=_xlfn.XLOOKUP(Constituencies!$B6,Candidates[[number]:[number]],Candidates[districtQid])} -> Q1419703 | I6: {=_xlfn.XLOOKUP(Constituencies!$B6,Candidates[[number]:[number]],Candidates[qid])} -> Q13111113 | J6: {=IF(_xlfn.XLOOKUP(Constituencies!$B6,Candidates[[number]:[number]],Candidates[reservation])="","GEN", _xlfn.XLOOKUP(Constituencies!$B6,Candidates[[number]:[number]],Candidates[reservation]))} -> GEN | K6: {=_xlfn.XLOOKUP(Constituencies!$B6,Candidates[[number]:[number]],Candidates[votersMale])} -> 109008 | L6: {=_xlfn.XLOOKUP(Constituencies!$B6,Candidates[[number]:[number]],Candidates[votersFemale])} -> 114966 | M6: {=_xlfn.XLOOKUP(Constituencies!$B6,Candidates[[number]:[number]],Candidates[votersTotal])} -> 223980 | N6: {=_xlfn.XLOOKUP(Constituencies!$B6,Candidates[[number]:[number]],Candidates[pollingBooths])} -> 239
B7: 5 | C7: {=_xlfn.XLOOKUP(Constituencies!$B7,Candidates[[number]:[number]],Candidates[name])} -> Thrikaripur | D7: {=_xlfn.XLOOKUP(Constituencies!$B7,Candidates[[number]:[number]],Candidates[nameMalayalam])} -> തൃക്കരിപ്പൂർ | E7: =_xlfn.XLOOKUP(Constituency[[#This Row],[Constituency]],Vote_History[constituency],Vote_History[ParliamentaryConstituency]) -> Kasaragod | F7: {=_xlfn.XLOOKUP(Constituencies!$B7,Candidates[[number]:[number]],Candidates[district])} -> Kasaragod | G7: {=_xlfn.XLOOKUP(Constituencies!$B7,Candidates[[number]:[number]],Candidates[districtMalayalam])} -> കാസർഗോഡ് ജില്ല | H7: {=_xlfn.XLOOKUP(Constituencies!$B7,Candidates[[number]:[number]],Candidates[districtQid])} -> Q1419703 | I7: {=_xlfn.XLOOKUP(Constituencies!$B7,Candidates[[number]:[number]],Candidates[qid])} -> Q16137696 | J7: {=IF(_xlfn.XLOOKUP(Constituencies!$B7,Candidates[[number]:[number]],Candidates[reservation])="","GEN", _xlfn.XLOOKUP(Constituencies!$B7,Candidates[[number]:[number]],Candidates[reservation]))} -> GEN | K7: {=_xlfn.XLOOKUP(Constituencies!$B7,Candidates[[number]:[number]],Candidates[votersMale])} -> 102044 | L7: {=_xlfn.XLOOKUP(Constituencies!$B7,Candidates[[number]:[number]],Candidates[votersFemale])} -> 108044 | M7: {=_xlfn.XLOOKUP(Constituencies!$B7,Candidates[[number]:[number]],Candidates[votersTotal])} -> 210090 | N7: {=_xlfn.XLOOKUP(Constituencies!$B7,Candidates[[number]:[number]],Candidates[pollingBooths])} -> 218
B8: 6 | C8: {=_xlfn.XLOOKUP(Constituencies!$B8,Candidates[[number]:[number]],Candidates[name])} -> Payyanur | D8: {=_xlfn.XLOOKUP(Constituencies!$B8,Candidates[[number]:[number]],Candidates[nameMalayalam])} -> പയ്യന്നൂർ | E8: =_xlfn.XLOOKUP(Constituency[[#This Row],[Constituency]],Vote_History[constituency],Vote_History[ParliamentaryConstituency]) -> Kasaragod | F8: {=_xlfn.XLOOKUP(Constituencies!$B8,Candidates[[number]:[number]],Candidates[district])} -> Kannur | G8: {=_xlfn.XLOOKUP(Constituencies!$B8,Candidates[[number]:[number]],Candidates[districtMalayalam])} -> കണ്ണൂർ ജില്ല | H8: {=_xlfn.XLOOKUP(Constituencies!$B8,Candidates[[number]:[number]],Candidates[districtQid])} -> Q2980652 | I8: {=_xlfn.XLOOKUP(Constituencies!$B8,Candidates[[number]:[number]],Candidates[qid])} -> Q17379122 | J8: {=IF(_xlfn.XLOOKUP(Constituencies!$B8,Candidates[[number]:[number]],Candidates[reservation])="","GEN", _xlfn.XLOOKUP(Constituencies!$B8,Candidates[[number]:[number]],Candidates[reservation]))} -> GEN | K8: {=_xlfn.XLOOKUP(Constituencies!$B8,Candidates[[number]:[number]],Candidates[votersMale])} -> 91006 | L8: {=_xlfn.XLOOKUP(Constituencies!$B8,Candidates[[number]:[number]],Candidates[votersFemale])} -> 97926 | M8: {=_xlfn.XLOOKUP(Constituencies!$B8,Candidates[[number]:[number]],Candidates[votersTotal])} -> 188935 | N8: {=_xlfn.XLOOKUP(Constituencies!$B8,Candidates[[number]:[number]],Candidates[pollingBooths])} -> 192
B9: 7 | C9: {=_xlfn.XLOOKUP(Constituencies!$B9,Candidates[[number]:[number]],Candidates[name])} -> Kalliasseri | D9: {=_xlfn.XLOOKUP(Constituencies!$B9,Candidates[[number]:[number]],Candidates[nameMalayalam])} -> കല്ല്യാശ്ശേരി | E9: =_xlfn.XLOOKUP(Constituency[[#This Row],[Constituency]],Vote_History[constituency],Vote_History[ParliamentaryConstituency]) -> Kasaragod | F9: {=_xlfn.XLOOKUP(Constituencies!$B9,Candidates[[number]:[number]],Candidates[district])} -> Kannur | G9: {=_xlfn.XLOOKUP(Constituencies!$B9,Candidates[[number]:[number]],Candidates[districtMalayalam])} -> കണ്ണൂർ ജില്ല | H9: {=_xlfn.XLOOKUP(Constituencies!$B9,Candidates[[number]:[number]],Candidates[districtQid])} -> Q2980652 | I9: {=_xlfn.XLOOKUP(Constituencies!$B9,Candidates[[number]:[number]],Candidates[qid])} -> Q13111077 | J9: {=IF(_xlfn.XLOOKUP(Constituencies!$B9,Candidates[[number]:[number]],Candidates[reservation])="","GEN", _xlfn.XLOOKUP(Constituencies!$B9,Candidates[[number]:[number]],Candidates[reservation]))} -> GEN | K9: {=_xlfn.XLOOKUP(Constituencies!$B9,Candidates[[number]:[number]],Candidates[votersMale])} -> 97648 | L9: {=_xlfn.XLOOKUP(Constituencies!$B9,Candidates[[number]:[number]],Candidates[votersFemale])} -> 106147 | M9: {=_xlfn.XLOOKUP(Constituencies!$B9,Candidates[[number]:[number]],Candidates[votersTotal])} -> 203796 | N9: {=_xlfn.XLOOKUP(Constituencies!$B9,Candidates[[number]:[number]],Candidates[pollingBooths])} -> 184
B10: 8 | C10: {=_xlfn.XLOOKUP(Constituencies!$B10,Candidates[[number]:[number]],Candidates[name])} -> Taliparamba | D10: {=_xlfn.XLOOKUP(Constituencies!$B10,Candidates[[number]:[number]],Candidates[nameMalayalam])} -> തളിപ്പറമ്പ് | E10: =_xlfn.XLOOKUP(Constituency[[#This Row],[Constituency]],Vote_History[constituency],Vote_History[ParliamentaryConstituency]) -> Kannur | F10: {=_xlfn.XLOOKUP(Constituencies!$B10,Candidates[[number]:[number]],Candidates[district])} -> Kannur | G10: {=_xlfn.XLOOKUP(Constituencies!$B10,Candidates[[number]:[number]],Candidates[districtMalayalam])} -> കണ്ണൂർ ജില്ല | H10: {=_xlfn.XLOOKUP(Constituencies!$B10,Candidates[[number]:[number]],Candidates[districtQid])} -> Q2980652 | I10: {=_xlfn.XLOOKUP(Constituencies!$B10,Candidates[[number]:[number]],Candidates[qid])} -> Q17379268 | J10: {=IF(_xlfn.XLOOKUP(Constituencies!$B10,Candidates[[number]:[number]],Candidates[reservation])="","GEN", _xlfn.XLOOKUP(Constituencies!$B10,Candidates[[number]:[number]],Candidates[reservation]))} -> GEN | K10: {=_xlfn.XLOOKUP(Constituencies!$B10,Candidates[[number]:[number]],Candidates[votersMale])} -> 111926 | L10: {=_xlfn.XLOOKUP(Constituencies!$B10,Candidates[[number]:[number]],Candidates[votersFemale])} -> 120353 | M10: {=_xlfn.XLOOKUP(Constituencies!$B10,Candidates[[number]:[number]],Candidates[votersTotal])} -> 232280 | N10: {=_xlfn.XLOOKUP(Constituencies!$B10,Candidates[[number]:[number]],Candidates[pollingBooths])} -> 233
B11: 9 | C11: {=_xlfn.XLOOKUP(Constituencies!$B11,Candidates[[number]:[number]],Candidates[name])} -> Irikkur | D11: {=_xlfn.XLOOKUP(Constituencies!$B11,Candidates[[number]:[number]],Candidates[nameMalayalam])} -> ഇരിക്കൂർ | E11: =_xlfn.XLOOKUP(Constituency[[#This Row],[Constituency]],Vote_History[constituency],Vote_History[ParliamentaryConstituency]) -> Kannur | F11: {=_xlfn.XLOOKUP(Constituencies!$B11,Candidates[[number]:[number]],Candidates[district])} -> Kannur | G11: {=_xlfn.XLOOKUP(Constituencies!$B11,Candidates[[number]:[number]],Candidates[districtMalayalam])} -> കണ്ണൂർ ജില്ല | H11: {=_xlfn.XLOOKUP(Constituencies!$B11,Candidates[[number]:[number]],Candidates[districtQid])} -> Q2980652 | I11: {=_xlfn.XLOOKUP(Constituencies!$B11,Candidates[[number]:[number]],Candidates[qid])} -> Q13110432 | J11: {=IF(_xlfn.XLOOKUP(Constituencies!$B11,Candidates[[number]:[number]],Candidates[reservation])="","GEN", _xlfn.XLOOKUP(Constituencies!$B11,Candidates[[number]:[number]],Candidates[reservation]))} -> GEN | K11: {=_xlfn.XLOOKUP(Constituencies!$B11,Candidates[[number]:[number]],Candidates[votersMale])} -> 98862 | L11: {=_xlfn.XLOOKUP(Constituencies!$B11,Candidates[[number]:[number]],Candidates[votersFemale])} -> 100464 | M11: {=_xlfn.XLOOKUP(Constituencies!$B11,Candidates[[number]:[number]],Candidates[votersTotal])} -> 199326 | N11: {=_xlfn.XLOOKUP(Constituencies!$B11,Candidates[[number]:[number]],Candidates[pollingBooths])} -> 214
B12: 10 | C12: {=_xlfn.XLOOKUP(Constituencies!$B12,Candidates[[number]:[number]],Candidates[name])} -> Azhikode | D12: {=_xlfn.XLOOKUP(Constituencies!$B12,Candidates[[number]:[number]],Candidates[nameMalayalam])} -> അഴീക്കോട് | E12: =_xlfn.XLOOKUP(Constituency[[#This Row],[Constituency]],Vote_History[constituency],Vote_History[ParliamentaryConstituency]) -> Kannur | F12: {=_xlfn.XLOOKUP(Constituencies!$B12,Candidates[[number]:[number]],Candidates[district])} -> Kannur | G12: {=_xlfn.XLOOKUP(Constituencies!$B12,Candidates[[number]:[number]],Candidates[districtMalayalam])} -> കണ്ണൂർ ജില്ല | H12: {=_xlfn.XLOOKUP(Constituencies!$B12,Candidates[[number]:[number]],Candidates[districtQid])} -> Q2980652 | I12: {=_xlfn.XLOOKUP(Constituencies!$B12,Candidates[[number]:[number]],Candidates[qid])} -> Q13110133 | J12: {=IF(_xlfn.XLOOKUP(Constituencies!$B12,Candidates[[number]:[number]],Candidates[reservation])="","GEN", _xlfn.XLOOKUP(Constituencies!$B12,Candidates[[number]:[number]],Candidates[reservation]))} -> GEN | K12: {=_xlfn.XLOOKUP(Constituencies!$B12,Candidates[[number]:[number]],Candidates[votersMale])} -> 89967 | L12: {=_xlfn.XLOOKUP(Constituencies!$B12,Candidates[[number]:[number]],Candidates[votersFemale])} -> 98280 | M12: {=_xlfn.XLOOKUP(Constituencies!$B12,Candidates[[number]:[number]],Candidates[votersTotal])} -> 188250 | N12: {=_xlfn.XLOOKUP(Constituencies!$B12,Candidates[[number]:[number]],Candidates[pollingBooths])} -> 185
B13: 11 | C13: {=_xlfn.XLOOKUP(Constituencies!$B13,Candidates[[number]:[number]],Candidates[name])} -> Kannur | D13: {=_xlfn.XLOOKUP(Constituencies!$B13,Candidates[[number]:[number]],Candidates[nameMalayalam])} -> കണ്ണൂർ | E13: =_xlfn.XLOOKUP(Constituency[[#This Row],[Constituency]],Vote_History[constituency],Vote_History[ParliamentaryConstituency]) -> Kannur | F13: {=_xlfn.XLOOKUP(Constituencies!$B13,Candidates[[number]:[number]],Candidates[district])} -> Kannur | G13: {=_xlfn.XLOOKUP(Constituencies!$B13,Candidates[[number]:[number]],Candidates[districtMalayalam])} -> കണ്ണൂർ ജില്ല | H13: {=_xlfn.XLOOKUP(Constituencies!$B13,Candidates[[number]:[number]],Candidates[districtQid])} -> Q2980652 | I13: {=_xlfn.XLOOKUP(Constituencies!$B13,Candidates[[number]:[number]],Candidates[qid])} -> Q16137348 | J13: {=IF(_xlfn.XLOOKUP(Constituencies!$B13,Candidates[[number]:[number]],Candidates[reservation])="","GEN", _xlfn.XLOOKUP(Constituencies!$B13,Candidates[[number]:[number]],Candidates[reservation]))} -> GEN | K13: {=_xlfn.XLOOKUP(Constituencies!$B13,Candidates[[number]:[number]],Candidates[votersMale])} -> 87817 | L13: {=_xlfn.XLOOKUP(Constituencies!$B13,Candidates[[number]:[number]],Candidates[votersFemale])} -> 94865 | M13: {=_xlfn.XLOOKUP(Constituencies!$B13,Candidates[[number]:[number]],Candidates[votersTotal])} -> 182682 | N13: {=_xlfn.XLOOKUP(Constituencies!$B13,Candidates[[number]:[number]],Candidates[pollingBooths])} -> 179
B14: 12 | C14: {=_xlfn.XLOOKUP(Constituencies!$B14,Candidates[[number]:[number]],Candidates[name])} -> Dharmadom | D14: {=_xlfn.XLOOKUP(Constituencies!$B14,Candidates[[number]:[number]],Candidates[nameMalayalam])} -> ധർമ്മടം | E14: =_xlfn.XLOOKUP(Constituency[[#This Row],[Constituency]],Vote_History[constituency],Vote_History[ParliamentaryConstituency]) -> Kannur | F14: {=_xlfn.XLOOKUP(Constituencies!$B14,Candidates[[number]:[number]],Candidates[district])} -> Kannur | G14: {=_xlfn.XLOOKUP(Constituencies!$B14,Candidates[[number]:[number]],Candidates[districtMalayalam])} -> കണ്ണൂർ ജില്ല | H14: {=_xlfn.XLOOKUP(Constituencies!$B14,Candidates[[number]:[number]],Candidates[districtQid])} -> Q2980652 | I14: {=_xlfn.XLOOKUP(Constituencies!$B14,Candidates[[number]:[number]],Candidates[qid])} -> Q13112766 | J14: {=IF(_xlfn.XLOOKUP(Constituencies!$B14,Candidates[[number]:[number]],Candidates[reservation])="","GEN", _xlfn.XLOOKUP(Constituencies!$B14,Candidates[[number]:[number]],Candidates[reservation]))} -> GEN | K14: {=_xlfn.XLOOKUP(Constituencies!$B14,Candidates[[number]:[number]],Candidates[votersMale])} -> 98049 | L14: {=_xlfn.XLOOKUP(Constituencies!$B14,Candidates[[number]:[number]],Candidates[votersFemale])} -> 107950 | M14: {=_xlfn.XLOOKUP(Constituencies!$B14,Candidates[[number]:[number]],Candidates[votersTotal])} -> 206000 | N14: {=_xlfn.XLOOKUP(Constituencies!$B14,Candidates[[number]:[number]],Candidates[pollingBooths])} -> 198
... B142: 140 | C142: {=_xlfn.XLOOKUP(Constituencies!$B142,Candidates[[number]:[number]],Candidates[name])} -> Neyyattinkara | D142: {=_xlfn.XLOOKUP(Constituencies!$B142,Candidates[[number]:[number]],Candidates[nameMalayalam])} -> നെയ്യാറ്റിൻകര | E142: =_xlfn.XLOOKUP(Constituency[[#This Row],[Constituency]],Vote_History[constituency],Vote_History[ParliamentaryConstituency]) -> Thiruvananthapuram | F142: {=_xlfn.XLOOKUP(Constituencies!$B142,Candidates[[number]:[number]],Candidates[district])} -> Thiruvananthapuram | G142: {=_xlfn.XLOOKUP(Constituencies!$B142,Candidates[[number]:[number]],Candidates[districtMalayalam])} -> തിരുവനന്തപുരം ജില്ല | H142: {=_xlfn.XLOOKUP(Constituencies!$B142,Candidates[[number]:[number]],Candidates[districtQid])} -> Q162612 | I142: {=_xlfn.XLOOKUP(Constituencies!$B142,Candidates[[number]:[number]],Candidates[qid])} -> Q16136265 | J142: {=IF(_xlfn.XLOOKUP(Constituencies!$B142,Candidates[[number]:[number]],Candidates[reservation])="","GEN", _xlfn.XLOOKUP(Constituencies!$B142,Candidates[[number]:[number]],Candidates[reservation]))} -> GEN | K142: {=_xlfn.XLOOKUP(Constituencies!$B142,Candidates[[number]:[number]],Candidates[votersMale])} -> 82177 | L142: {=_xlfn.XLOOKUP(Constituencies!$B142,Candidates[[number]:[number]],Candidates[votersFemale])} -> 85199 | M142: {=_xlfn.XLOOKUP(Constituencies!$B142,Candidates[[number]:[number]],Candidates[votersTotal])} -> 167377 | N142: {=_xlfn.XLOOKUP(Constituencies!$B142,Candidates[[number]:[number]],Candidates[pollingBooths])} -> 214

Sheet Others
B2: Parliament_Const | C2: Parliament_Const_ML | F2: Kasaragod | G2: Kannur | H2: Wayanad | I2: Kozhikode | J2: Malappuram | K2: Palakkad | L2: Thrissur | M2: Ernakulam | N2: Idukki | O2: Kottayam | P2: Alappuzha | Q2: Pathanamthitta | R2: Kollam | S2: Thiruvananthapuram
B3: Kasaragod | C3: കാസർഗോഡ് | F3: Manjeshwaram | G3: Payyanur | H3: Mananthavady | I3: Vatakara | J3: Kondotty | K3: Thrithala | L3: Chelakkara | M3: Perumbavoor | N3: Devikulam | O3: Pala | P3: Aroor | Q3: Thiruvalla | R3: Karunagappally | S3: Varkala
B4: Kannur | C4: കണ്ണൂർ | F4: Kasaragod | G4: Kalliasseri | H4: Sulthan Bathery | I4: Kuttiady | J4: Eranad | K4: Pattambi | L4: Kunnamkulam | M4: Angamaly | N4: Udumbanchola | O4: Kaduthuruthy | P4: Cherthala | Q4: Ranni | R4: Chavara | S4: Attingal
B5: Vadakara | C5: വടകര | F5: Udma | G5: Taliparamba | H5: Kalpetta | I5: Nadapuram | J5: Nilambur | K5: Shornur | L5: Guruvayur | M5: Aluva | N5: Thodupuzha | O5: Vaikom | P5: Alappuzha | Q5: Aranmula | R5: Kunnathur | S5: Chirayinkeezhu
B6: Wayanad | C6: വയനാട് | F6: Kanhangad | G6: Irikkur | I6: Koyilandy | J6: Wandoor | K6: Ottapalam | L6: Manalur | M6: Kalamassery | N6: Idukki | O6: Ettumanoor | P6: Ambalappuzha | Q6: Konni | R6: Kottarakkara | S6: Nedumangad
B7: Kozhikode | C7: കോഴിക്കോട് | F7: Thrikaripur | G7: Azhikode | I7: Perambra | J7: Manjeri | K7: Kongad | L7: Wadakkanchery | M7: Paravur | N7: Peerumade | O7: Kottayam | P7: Kuttanad | Q7: Adoor | R7: Pathanapuram | S7: Vamanapuram
B8: Malappuram | C8: മലപ്പുറം | G8: Kannur | I8: Balussery | J8: Perinthalmanna | K8: Mannarkkad | L8: Ollur | M8: Vypin | O8: Puthuppally | P8: Haripad | R8: Punalur | S8: Kazhakkoottam
B9: Ponnani | C9: പൊന്നാനി | G9: Dharmadom | I9: Elathur | J9: Mankada | K9: Malampuzha | L9: Thrissur | M9: Kochi | O9: Changanassery | P9: Kayamkulam | R9: Chadayamangalam | S9: Vattiyoorkavu
B10: Palakkad | C10: പാലക്കാട് | G10: Thalassery | I10: Kozhikode North | J10: Malappuram | K10: Palakkad | L10: Nattika | M10: Thrippunithura | O10: Kanjirappally | P10: Mavelikara | R10: Kundara | S10: Thiruvananthapuram
B11: Alathur | C11: ആലത്തൂർ | G11: Kuthuparamba | I11: Kozhikode South | J11: Vengara | K11: Tarur | L11: Kaipamangalam | M11: Ernakulam | O11: Poonjar | P11: Chengannur | R11: Kollam | S11: Nemom
B12: Thrissur | C12: തൃശ്ശൂർ | G12: Mattanur | I12: Beypore | J12: Vallikkunnu | K12: Chittur | L12: Irinjalakuda | M12: Thrikkakara | R12: Eravipuram | S12: Aruvikkara
B13: Chalakudy | C13: ചാലക്കുടി | G13: Peravoor | I13: Kunnamangalam | J13: Tirurangadi | K13: Nenmara | L13: Puthukkad | M13: Kunnathunad | R13: Chathannoor | S13: Parassala
B14: Ernakulam | C14: എറണാകുളം | I14: Koduvally | J14: Tanur | K14: Alathur | L14: Chalakudy | M14: Piravom | S14: Kattakkada
B15: Kottayam | C15: കോട്ടയം | I15: Thiruvambady | J15: Tirur | L15: Kodungallur | M15: Muvattupuzha | S15: Kovalam
B16: Idukki | C16: ഇടുക്കി | J16: Kottakkal | M16: Kothamangalam | S16: Neyyattinkara
B17: Mavelikara | C17: മാവേലിക്കര | J17: Thavanur
B18: Pathanamthitta | C18: പത്തനംതിട്ട | J18: Ponnani
B19: Alappuzha | C19: ആലപ്പുഴ
B20: Kollam | C20: കൊല്ലം
B21: Attingal | C21: ആറ്റിങ്ങൽ
B22: Thiruvananthapuram | C22: തിരുവനന്തപുരം | F22: Lokshabha and Niyamasabha Combined
G23: 2011 | H23: 2014 | I23: 2016 | J23: 2019 | K23: 2021 | L23: 2024 | M23: 2026
B24: Short | C24: Party | D24: Alliance | F24: Allience | G24: AE 2011 | H24: GE 2014 | I24: AE 2016 | J24: GE 2019 | K24: AE 2021 | L24: GE 2024 | M24: AE 2026
B25: CPI(M) | C25: Communist Party of India (Marxist) | D25: LDF | F25: LDF | G25: {=_xlfn._xlws.FILTER(Vote_History[[AllianceVotes__LDF]:[AllianceVotes__LDF]],(Vote_History[[Year]:[Year]]=G$23)*(Vote_History[[Number]:[Number]]=No_Selected_Constituency))} -> 73190 | H25: {=_xlfn._xlws.FILTER(Vote_History[[AllianceVotes__LDF]:[AllianceVotes__LDF]],(Vote_History[[Year]:[Year]]=H$23)*(Vote_History[[Number]:[Number]]=No_Selected_Constituency))} -> 71205 | I25: {=_xlfn._xlws.FILTER(Vote_History[[AllianceVotes__LDF]:[AllianceVotes__LDF]],(Vote_History[[Year]:[Year]]=I$23)*(Vote_History[[Number]:[Number]]=No_Selected_Constituency))} -> 83006 | J25: {=_xlfn._xlws.FILTER(Vote_History[[AllianceVotes__LDF]:[AllianceVotes__LDF]],(Vote_History[[Year]:[Year]]=J$23)*(Vote_History[[Number]:[Number]]=No_Selected_Constituency))} -> 73542 | K25: {=_xlfn._xlws.FILTER(Vote_History[[AllianceVotes__LDF]:[AllianceVotes__LDF]],(Vote_History[[Year]:[Year]]=K$23)*(Vote_History[[Number]:[Number]]=No_Selected_Constituency))} -> 88252 | L25: {=_xlfn._xlws.FILTER(Vote_History[[AllianceVotes__LDF]:[AllianceVotes__LDF]],(Vote_History[[Year]:[Year]]=L$23)*(Vote_History[[Number]:[Number]]=No_Selected_Constituency))} -> 65405 | M25: {=_xlfn._xlws.FILTER(Result2026[Votes],(Result2026[Alliance]=F25)*(Result2026[Number]=No_Selected_Constituency))} -> 81428
B26: CPI | C26: Communist Party of India | D26: LDF | F26: UDF | G26: {=_xlfn._xlws.FILTER(Vote_History[[AllianceVotes__UDF]:[AllianceVotes__UDF]],(Vote_History[[Year]:[Year]]=G$23)*(Vote_History[[Number]:[Number]]=No_Selected_Constituency))} -> 43244 | H26: {=_xlfn._xlws.FILTER(Vote_History[[AllianceVotes__UDF]:[AllianceVotes__UDF]],(Vote_History[[Year]:[Year]]=H$23)*(Vote_History[[Number]:[Number]]=No_Selected_Constituency))} -> 48423 | I26: {=_xlfn._xlws.FILTER(Vote_History[[AllianceVotes__UDF]:[AllianceVotes__UDF]],(Vote_History[[Year]:[Year]]=I$23)*(Vote_History[[Number]:[Number]]=No_Selected_Constituency))} -> 40115 | J26: {=_xlfn._xlws.FILTER(Vote_History[[AllianceVotes__UDF]:[AllianceVotes__UDF]],(Vote_History[[Year]:[Year]]=J$23)*(Vote_History[[Number]:[Number]]=No_Selected_Constituency))} -> 59848 | K26: {=_xlfn._xlws.FILTER(Vote_History[[AllianceVotes__UDF]:[AllianceVotes__UDF]],(Vote_History[[Year]:[Year]]=K$23)*(Vote_History[[Number]:[Number]]=No_Selected_Constituency))} -> 43859 | L26: {=_xlfn._xlws.FILTER(Vote_History[[AllianceVotes__UDF]:[AllianceVotes__UDF]],(Vote_History[[Year]:[Year]]=L$23)*(Vote_History[[Number]:[Number]]=No_Selected_Constituency))} -> 64347 | M26: {=_xlfn._xlws.FILTER(Result2026[Votes],(Result2026[Alliance]=F26)*(Result2026[Number]=No_Selected_Constituency))} -> 62995
B27: Kerala Congress (M) | C27: Kerala Congress (Mani) | D27: LDF | F27: NDA | G27: {=_xlfn._xlws.FILTER(Vote_History[[AllianceVotes__NDA]:[AllianceVotes__NDA]],(Vote_History[[Year]:[Year]]=G$23)*(Vote_History[[Number]:[Number]]=No_Selected_Constituency))} -> 5499 | H27: {=_xlfn._xlws.FILTER(Vote_History[[AllianceVotes__NDA]:[AllianceVotes__NDA]],(Vote_History[[Year]:[Year]]=H$23)*(Vote_History[[Number]:[Number]]=No_Selected_Constituency))} -> 10758 | I27: {=_xlfn._xlws.FILTER(Vote_History[[AllianceVotes__NDA]:[AllianceVotes__NDA]],(Vote_History[[Year]:[Year]]=I$23)*(Vote_History[[Number]:[Number]]=No_Selected_Constituency))} -> 11036 | J27: {=_xlfn._xlws.FILTER(Vote_History[[AllianceVotes__NDA]:[AllianceVotes__NDA]],(Vote_History[[Year]:[Year]]=J$23)*(Vote_History[[Number]:[Number]]=No_Selected_Constituency))} -> 9854 | K27: {=_xlfn._xlws.FILTER(Vote_History[[AllianceVotes__NDA]:[AllianceVotes__NDA]],(Vote_History[[Year]:[Year]]=K$23)*(Vote_History[[Number]:[Number]]=No_Selected_Constituency))} -> 11365 | L27: {=_xlfn._xlws.FILTER(Vote_History[[AllianceVotes__NDA]:[AllianceVotes__NDA]],(Vote_History[[Year]:[Year]]=L$23)*(Vote_History[[Number]:[Number]]=No_Selected_Constituency))} -> 17688 | M27: {=_xlfn._xlws.FILTER(Result2026[Votes],(Result2026[Alliance]=F27)*(Result2026[Number]=No_Selected_Constituency))} -> 13110
B28: Indian Socialist Janata Dal | C28: Indian Socialist Janata Dal | D28: LDF
B29: NCP(SP) | C29: Nationalist Congress Party (Sharadchandra Pawar) | D29: LDF | F29: Niyamasabha | K29: Loksabha
B30: RJD | C30: Rashtriya Janata Dal | D30: LDF | F30: Allience | G30: 2011 | H30: 2016 | I30: 2021 | J30: 2026 | L30: Allience | M30: 2014 | N30: 2019 | O30: 2024
B31: INL | C31: Indian National League | D31: LDF | F31: LDF | G31: {=_xlfn._xlws.FILTER(Vote_History[[AllianceVotes__LDF]:[AllianceVotes__LDF]],(Vote_History[[Year]:[Year]]=G$30)*(Vote_History[[Number]:[Number]]=No_Selected_Constituency))} -> 73190 | H31: {=_xlfn._xlws.FILTER(Vote_History[[AllianceVotes__LDF]:[AllianceVotes__LDF]],(Vote_History[[Year]:[Year]]=H$30)*(Vote_History[[Number]:[Number]]=No_Selected_Constituency))} -> 83006 | I31: {=_xlfn._xlws.FILTER(Vote_History[[AllianceVotes__LDF]:[AllianceVotes__LDF]],(Vote_History[[Year]:[Year]]=I$30)*(Vote_History[[Number]:[Number]]=No_Selected_Constituency))} -> 88252 | J31: {=_xlfn._xlws.FILTER(Result2026[Votes],(Result2026[Alliance]=F31)*(Result2026[Number]=No_Selected_Constituency))} -> 81428 | L31: LDF | M31: {=_xlfn._xlws.FILTER(Vote_History[[AllianceVotes__LDF]:[AllianceVotes__LDF]],(Vote_History[[Year]:[Year]]=M$30)*(Vote_History[[Number]:[Number]]=No_Selected_Constituency))} -> 71205 | N31: {=_xlfn._xlws.FILTER(Vote_History[[AllianceVotes__LDF]:[AllianceVotes__LDF]],(Vote_History[[Year]:[Year]]=N$30)*(Vote_History[[Number]:[Number]]=No_Selected_Constituency))} -> 73542 | O31: {=_xlfn._xlws.FILTER(Vote_History[[AllianceVotes__LDF]:[AllianceVotes__LDF]],(Vote_History[[Year]:[Year]]=O$30)*(Vote_History[[Number]:[Number]]=No_Selected_Constituency))} -> 65405
B32: Congress (Secular) | C32: Congress (Secular) | D32: LDF | F32: UDF | G32: {=_xlfn._xlws.FILTER(Vote_History[[AllianceVotes__UDF]:[AllianceVotes__UDF]],(Vote_History[[Year]:[Year]]=G$30)*(Vote_History[[Number]:[Number]]=No_Selected_Constituency))} -> 43244 | H32: {=_xlfn._xlws.FILTER(Vote_History[[AllianceVotes__UDF]:[AllianceVotes__UDF]],(Vote_History[[Year]:[Year]]=H$30)*(Vote_History[[Number]:[Number]]=No_Selected_Constituency))} -> 40115 | I32: {=_xlfn._xlws.FILTER(Vote_History[[AllianceVotes__UDF]:[AllianceVotes__UDF]],(Vote_History[[Year]:[Year]]=I$30)*(Vote_History[[Number]:[Number]]=No_Selected_Constituency))} -> 43859 | J32: {=_xlfn._xlws.FILTER(Result2026[Votes],(Result2026[Alliance]=F32)*(Result2026[Number]=No_Selected_Constituency))} -> 62995 | L32: UDF | M32: {=_xlfn._xlws.FILTER(Vote_History[[AllianceVotes__UDF]:[AllianceVotes__UDF]],(Vote_History[[Year]:[Year]]=M$30)*(Vote_History[[Number]:[Number]]=No_Selected_Constituency))} -> 48423 | N32: {=_xlfn._xlws.FILTER(Vote_History[[AllianceVotes__UDF]:[AllianceVotes__UDF]],(Vote_History[[Year]:[Year]]=N$30)*(Vote_History[[Number]:[Number]]=No_Selected_Constituency))} -> 59848 | O32: {=_xlfn._xlws.FILTER(Vote_History[[AllianceVotes__UDF]:[AllianceVotes__UDF]],(Vote_History[[Year]:[Year]]=O$30)*(Vote_History[[Number]:[Number]]=No_Selected_Constituency))} -> 64347
B33: Kerala Congress (B) | C33: Kerala Congress (B) | D33: LDF | F33: NDA | G33: {=_xlfn._xlws.FILTER(Vote_History[[AllianceVotes__NDA]:[AllianceVotes__NDA]],(Vote_History[[Year]:[Year]]=G$30)*(Vote_History[[Number]:[Number]]=No_Selected_Constituency))} -> 5499 | H33: {=_xlfn._xlws.FILTER(Vote_History[[AllianceVotes__NDA]:[AllianceVotes__NDA]],(Vote_History[[Year]:[Year]]=H$30)*(Vote_History[[Number]:[Number]]=No_Selected_Constituency))} -> 11036 | I33: {=_xlfn._xlws.FILTER(Vote_History[[AllianceVotes__NDA]:[AllianceVotes__NDA]],(Vote_History[[Year]:[Year]]=I$30)*(Vote_History[[Number]:[Number]]=No_Selected_Constituency))} -> 11365 | J33: {=_xlfn._xlws.FILTER(Result2026[Votes],(Result2026[Alliance]=F33)*(Result2026[Number]=No_Selected_Constituency))} -> 13110 | L33: NDA | M33: {=_xlfn._xlws.FILTER(Vote_History[[AllianceVotes__NDA]:[AllianceVotes__NDA]],(Vote_History[[Year]:[Year]]=M$30)*(Vote_History[[Number]:[Number]]=No_Selected_Constituency))} -> 10758 | N33: {=_xlfn._xlws.FILTER(Vote_History[[AllianceVotes__NDA]:[AllianceVotes__NDA]],(Vote_History[[Year]:[Year]]=N$30)*(Vote_History[[Number]:[Number]]=No_Selected_Constituency))} -> 9854 | O33: {=_xlfn._xlws.FILTER(Vote_History[[AllianceVotes__NDA]:[AllianceVotes__NDA]],(Vote_History[[Year]:[Year]]=O$30)*(Vote_History[[Number]:[Number]]=No_Selected_Constituency))} -> 17688
B34: Janadhipathya Kerala Congress | C34: Janadhipathya Kerala Congress | D34: LDF
B35: Independent (CPI support) | C35: Independent (CPI support) | D35: LDF
B36: Independent (CPI(M) support) | C36: Independent (CPI(M) support) | D36: LDF
B37: Independent (INL Support) | C37: Independent (INL Support) | D37: LDF
B38: RSP(L) | C38: Revolutionary Socialist Party (Leninist) | D38: LDF
B39: INC | C39: Indian National Congress | D39: UDF
B40: IUML | C40: Indian Union Muslim League | D40: UDF
B41: KEC | C41: Kerala Congress | D41: UDF
...

Sheet Vote History
B2: QID | C2: Number | D2: constituency | E2: Election | F2: Year | G2: ParliamentaryConstituency | H2: Winner_Name | I2: Winner_Party | J2: Winner__Alliance | K2: Winner_Votes | L2: RunnerUp__Name | M2: RunnerUp_Party | N2: RunnerUp__Alliance | O2: RunnerUp_Votes | P2: RunnerUp2__Name | Q2: RunnerUp2__Party | R2: RunnerUp2_Alliance | S2: RunnerUp2_Votes | T2: Margin | U2: AllianceVotes__LDF | V2: AllianceVotes__UDF | W2: AllianceVotes__NDA | X2: AllianceVotes__Others | Y2: TotalVotes
B3: Q13113782 | C3: =_xlfn.XLOOKUP(Vote_History[[#This Row],[QID]],Constituency[qid],Constituency[Number]) -> 1 | D3: =_xlfn.XLOOKUP(Vote_History[[#This Row],[Number]],Constituency[Number],Constituency[Constituency]) -> Manjeshwaram | E3: niyamasabha | F3: 2011 | G3: Kasaragod | H3: P B Abdul Razak | I3: IUML | J3: UDF | K3: 49817 | L3: K Surendran | M3: BJP | N3: NDA | O3: 43989 | P3: Adv. C H Kunhambu | Q3: CPI(M) | R3: LDF | S3: 35067 | T3: 5828 | U3: 35067 | V3: 49817 | W3: 43989 | X3: 4100 | Y3: 132973
B4: Q13113782 | C4: =_xlfn.XLOOKUP(Vote_History[[#This Row],[QID]],Constituency[qid],Constituency[Number]) -> 1 | D4: =_xlfn.XLOOKUP(Vote_History[[#This Row],[Number]],Constituency[Number],Constituency[Constituency]) -> Manjeshwaram | E4: niyamasabha | F4: 2016 | G4: Kasaragod | H4: P B Abdul Razak | I4: IUML | J4: UDF | K4: 56870 | L4: K Surendran | M4: BJP | N4: NDA | O4: 56781 | P4: Adv. C.H.Kunhambu | Q4: CPI(M) | R4: LDF | S4: 42565 | T4: 89 | U4: 42565 | V4: 56870 | W4: 56781 | X4: 2022 | Y4: 158238
B5: Q13113782 | C5: =_xlfn.XLOOKUP(Vote_History[[#This Row],[QID]],Constituency[qid],Constituency[Number]) -> 1 | D5: =_xlfn.XLOOKUP(Vote_History[[#This Row],[Number]],Constituency[Number],Constituency[Constituency]) -> Manjeshwaram | E5: niyamasabha | F5: 2021 | G5: Kasaragod | H5: A K M Ashraf | I5: IUML | J5: UDF | K5: 65758 | L5: K Surendran | M5: BJP | N5: NDA | O5: 65013 | P5: V V Rameshan | Q5: CPI(M) | R5: LDF | S5: 40639 | T5: 745 | U5: 40639 | V5: 65758 | W5: 65013 | X5: 629 | Y5: 172039
B6: Q13113782 | C6: =_xlfn.XLOOKUP(Vote_History[[#This Row],[QID]],Constituency[qid],Constituency[Number]) -> 1 | D6: =_xlfn.XLOOKUP(Vote_History[[#This Row],[Number]],Constituency[Number],Constituency[Constituency]) -> Manjeshwaram | E6: loksabha | F6: 2014 | G6: Kasaragod | H6: Adv. T Siddique | I6: INC | J6: UDF | K6: 52459 | L6: K Surendran | M6: BJP | N6: NDA | O6: 46631 | P6: P Karunakaran | Q6: CPI(M) | R6: LDF | S6: 29433 | T6: 5828 | U6: 29433 | V6: 52459 | W6: 46631 | X6: 6521 | Y6: 135044
B7: Q13113782 | C7: =_xlfn.XLOOKUP(Vote_History[[#This Row],[QID]],Constituency[qid],Constituency[Number]) -> 1 | D7: =_xlfn.XLOOKUP(Vote_History[[#This Row],[Number]],Constituency[Number],Constituency[Constituency]) -> Manjeshwaram | E7: loksabha | F7: 2019 | G7: Kasaragod | H7: Rajmohan Unnithan | I7: INC | J7: UDF | K7: 68217 | L7: Ravisha Thanthri Kuntar | M7: BJP | N7: NDA | O7: 57104 | P7: K. P. Sathishchandran | Q7: CPI(M) | R7: LDF | S7: 32796 | T7: 11113 | U7: 32796 | V7: 68217 | W7: 57104 | X7: 2161 | Y7: 160278
B8: Q13113782 | C8: =_xlfn.XLOOKUP(Vote_History[[#This Row],[QID]],Constituency[qid],Constituency[Number]) -> 1 | D8: =_xlfn.XLOOKUP(Vote_History[[#This Row],[Number]],Constituency[Number],Constituency[Constituency]) -> Manjeshwaram | E8: loksabha | F8: 2024 | G8: Kasaragod | H8: Rajmohan Unnithan | I8: INC | J8: UDF | K8: 74437 | L8: M.L Ashwini | M8: BJP | N8: NDA | O8: 57179 | P8: M.V Balakrishnan Master | Q8: CPI(M) | R8: LDF | S8: 30156 | T8: 17258 | U8: 30156 | V8: 74437 | W8: 57179 | X8: 910 | Y8: 162682
B9: Q13111222 | C9: =_xlfn.XLOOKUP(Vote_History[[#This Row],[QID]],Constituency[qid],Constituency[Number]) -> 2 | D9: =_xlfn.XLOOKUP(Vote_History[[#This Row],[Number]],Constituency[Number],Constituency[Constituency]) -> Kasaragod | E9: niyamasabha | F9: 2011 | G9: Kasaragod | H9: N.A.Nellikkunnu | I9: IUML | J9: UDF | K9: 53068 | L9: Jayalakshmi N Bhat | M9: BJP | N9: NDA | O9: 43330 | P9: Azeez Kadappuram | Q9: INL | R9: LDF | S9: 16467 | T9: 9738 | U9: 16467 | V9: 53068 | W9: 43330 | X9: 4166 | Y9: 117031
B10: Q13111222 | C10: =_xlfn.XLOOKUP(Vote_History[[#This Row],[QID]],Constituency[qid],Constituency[Number]) -> 2 | D10: =_xlfn.XLOOKUP(Vote_History[[#This Row],[Number]],Constituency[Number],Constituency[Constituency]) -> Kasaragod | E10: niyamasabha | F10: 2016 | G10: Kasaragod | H10: N A Nellikkunnu | I10: IUML | J10: UDF | K10: 64727 | L10: Ravisha Thantri Kuntar | M10: BJP | N10: NDA | O10: 56120 | P10: Dr. A A Ameen | Q10: INL | R10: LDF | S10: 21615 | T10: 8607 | U10: 21615 | V10: 64727 | W10: 56120 | X10: 1626 | Y10: 144088
B11: Q13111222 | C11: =_xlfn.XLOOKUP(Vote_History[[#This Row],[QID]],Constituency[qid],Constituency[Number]) -> 2 | D11: =_xlfn.XLOOKUP(Vote_History[[#This Row],[Number]],Constituency[Number],Constituency[Constituency]) -> Kasaragod | E11: niyamasabha | F11: 2021 | G11: Kasaragod | H11: N A Nellikkunnu | I11: IUML | J11: UDF | K11: 63296 | L11: Adv K Shreekanth | M11: BJP | N11: NDA | O11: 50395 | P11: M A Latheef | Q11: INL | R11: LDF | S11: 28323 | T11: 12901 | U11: 28323 | V11: 63296 | W11: 50395 | X11: 1847 | Y11: 143861
B12: Q13111222 | C12: =_xlfn.XLOOKUP(Vote_History[[#This Row],[QID]],Constituency[qid],Constituency[Number]) -> 2 | D12: =_xlfn.XLOOKUP(Vote_History[[#This Row],[Number]],Constituency[Number],Constituency[Constituency]) -> Kasaragod | E12: loksabha | F12: 2014 | G12: Kasaragod | H12: Adv. T Siddique | I12: INC | J12: UDF | K12: 54426 | L12: K Surendran | M12: BJP | N12: NDA | O12: 41236 | P12: P Karunakaran | Q12: CPI(M) | R12: LDF | S12: 22827 | T12: 13190 | U12: 22827 | V12: 54426 | W12: 41236 | X12: 5757 | Y12: 124246
B13: Q13111222 | C13: =_xlfn.XLOOKUP(Vote_History[[#This Row],[QID]],Constituency[qid],Constituency[Number]) -> 2 | D13: =_xlfn.XLOOKUP(Vote_History[[#This Row],[Number]],Constituency[Number],Constituency[Constituency]) -> Kasaragod | E13: loksabha | F13: 2019 | G13: Kasaragod | H13: Rajmohan Unnithan | I13: INC | J13: UDF | K13: 69790 | L13: Ravisha Thanthri Kuntar | M13: BJP | N13: NDA | O13: 46630 | P13: K. P. Sathishchandran | Q13: CPI(M) | R13: LDF | S13: 28567 | T13: 23160 | U13: 28567 | V13: 69790 | W13: 46630 | X13: 1678 | Y13: 146665
B14: Q13111222 | C14: =_xlfn.XLOOKUP(Vote_History[[#This Row],[QID]],Constituency[qid],Constituency[Number]) -> 2 | D14: =_xlfn.XLOOKUP(Vote_History[[#This Row],[Number]],Constituency[Number],Constituency[Constituency]) -> Kasaragod | E14: loksabha | F14: 2024 | G14: Kasaragod | H14: Rajmohan Unnithan | I14: INC | J14: UDF | K14: 73407 | L14: M.L Ashwini | M14: BJP | N14: NDA | O14: 47032 | P14: M.V Balakrishnan Master | Q14: CPI(M) | R14: LDF | S14: 26162 | T14: 26375 | U14: 26162 | V14: 73407 | W14: 47032 | X14: 776 | Y14: 147377
... B842: Q16136265 | C842: =_xlfn.XLOOKUP(Vote_History[[#This Row],[QID]],Constituency[qid],Constituency[Number]) -> 140 | D842: =_xlfn.XLOOKUP(Vote_History[[#This Row],[Number]],Constituency[Number],Constituency[Constituency]) -> Neyyattinkara | E842: loksabha | F842: 2024 | G842: Thiruvananthapuram | H842: Shashi Tharoor | I842: INC | J842: UDF | K842: 58749 | L842: Rajeev Chandrasekhar | M842: BJP | N842: NDA | O842: 36136 | P842: Pannian Ravindran | Q842: CPI | R842: LDF | S842: 35526 | T842: 22613 | U842: 35526 | V842: 58749 | W842: 36136 | X842: 1160 | Y842: 131571

Sheet Ex MLA
B2: Number | C2: Constituency | D2: District | E2: Member | F2: Party | G2: Alliance | H2: Age | I2: Picture | J2: Total Voters | K2: Valid Votes | L2: Valid_Vote_Percentage | M2: Member_Votes | N2: Member_Perc | O2: Margin
